Workbook

Sheet Dashboard
A1: DASHBOARD
A4: Constituency Battlefield Class | B4: Seats
A5: Stronghold | B5: =COUNTIF('117 Battles '!$F$4:$F$120, A5) -> 22
A6: Lean | B6: =COUNTIF('117 Battles '!$F$4:$F$120, A6) -> 20
A7: Battleground | B7: =COUNTIF('117 Battles '!$F$4:$F$120, A7) -> 26
A8: Opposition Lean | B8: =COUNTIF('117 Battles '!$F$4:$F$120, A8) -> 20
A9: Highly Volatile | B9: =COUNTIF('117 Battles '!$F$4:$F$120, A9) -> 29
A11: 2027 Party-wise Strategic Posture as of September 2026
A12: Party | B12: Defend | C12: Battleground | D12: Expand | E12: Long Shot
B13: Party currently has a meaningful position/hold that needs protecting | C13: Party has a credible competitive pathway | D13: Opposition held seat where evidence suggests potential growth | E13: Current evidence does not show a strong near term pathway
A14: AAP | B14: {=COUNTIF(INDEX('117 Battles '!$T$4:$W$120, 0, MATCH($A14, {"AAP","INC","SAD","BJP"}, 0)), B$12)} -> 27 | C14: {=COUNTIF(INDEX('117 Battles '!$T$4:$W$120, 0, MATCH($A14, {"AAP","INC","SAD","BJP"}, 0)), C$12)} -> 72 | D14: {=COUNTIF(INDEX('117 Battles '!$T$4:$W$120, 0, MATCH($A14, {"AAP","INC","SAD","BJP"}, 0)), D$12)} -> 7 | E14: {=COUNTIF(INDEX('117 Battles '!$T$4:$W$120, 0, MATCH($A14, {"AAP","INC","SAD","BJP"}, 0)), E$12)} -> 11
A15: INC | B15: {=COUNTIF(INDEX('117 Battles '!$T$4:$W$120, 0, MATCH($A15, {"AAP","INC","SAD","BJP"}, 0)), B$12)} -> 11 | C15: {=COUNTIF(INDEX('117 Battles '!$T$4:$W$120, 0, MATCH($A15, {"AAP","INC","SAD","BJP"}, 0)), C$12)} -> 39 | D15: {=COUNTIF(INDEX('117 Battles '!$T$4:$W$120, 0, MATCH($A15, {"AAP","INC","SAD","BJP"}, 0)), D$12)} -> 28 | E15: {=COUNTIF(INDEX('117 Battles '!$T$4:$W$120, 0, MATCH($A15, {"AAP","INC","SAD","BJP"}, 0)), E$12)} -> 39
A16: SAD | B16: {=COUNTIF(INDEX('117 Battles '!$T$4:$W$120, 0, MATCH($A16, {"AAP","INC","SAD","BJP"}, 0)), B$12)} -> 1 | C16: {=COUNTIF(INDEX('117 Battles '!$T$4:$W$120, 0, MATCH($A16, {"AAP","INC","SAD","BJP"}, 0)), C$12)} -> 28 | D16: {=COUNTIF(INDEX('117 Battles '!$T$4:$W$120, 0, MATCH($A16, {"AAP","INC","SAD","BJP"}, 0)), D$12)} -> 20 | E16: {=COUNTIF(INDEX('117 Battles '!$T$4:$W$120, 0, MATCH($A16, {"AAP","INC","SAD","BJP"}, 0)), E$12)} -> 68
A17: BJP | B17: {=COUNTIF(INDEX('117 Battles '!$T$4:$W$120, 0, MATCH($A17, {"AAP","INC","SAD","BJP"}, 0)), B$12)} -> 2 | C17: {=COUNTIF(INDEX('117 Battles '!$T$4:$W$120, 0, MATCH($A17, {"AAP","INC","SAD","BJP"}, 0)), C$12)} -> 8 | D17: {=COUNTIF(INDEX('117 Battles '!$T$4:$W$120, 0, MATCH($A17, {"AAP","INC","SAD","BJP"}, 0)), D$12)} -> 14 | E17: {=COUNTIF(INDEX('117 Battles '!$T$4:$W$120, 0, MATCH($A17, {"AAP","INC","SAD","BJP"}, 0)), E$12)} -> 93
A19: Party | B19: Core Strategic Problem | C19: Priority Actionables
A20: AAP | B20: Protect a very large but exposed incumbent footprint | C20: Governance delivery Candidate correction Manage internal rebellion Protect Malwa organisational strength Track high-risk seats
A21: INC | B21: Convert opposition opportunity into Assembly seats | C21: Resolve factionalism Build Malwa organisation Candidate-first seat planning Activate booth network Present concrete policy alternatives
A22: BJP | B22: Convert expanded vote presence into constituencies | C22: Build seat-level organisation Expand rural credibility Integrate new recruits Clarify alliance structure Strengthen Punjab-specific leadership
A23: SAD | B23: Rebuild credibility and electoral relevance | C23: Political renewal Stabilise cadre/candidates Manage Panthic fragmentation Clarify alliance strategy Rebuild urban complement
A24: Emerging | B24: Convert local influence into durable organisation | C24: Concentrate on organisational depth Credible candidates Formalise structures Demonstrate multi-seat scalability
A27: Structural indicator | B27: AAP | C27: INC | D27: SAD | E27: BJP
A28: Phase 4 equal-weight analyst score /10 | B28: =ROUND(AVERAGE((B29/117)*10,(B30/117)*10,(B31/13)*10,(B32/40)*10,(B33/SUM($B$33:$E$33))*10,(B34/SUM($B$34:$E$34))*10) + 2.17, 2) -> 8.35 | C28: =ROUND(AVERAGE((C29/117)*10,(C30/117)*10,(C31/13)*10,(C32/40)*10,(C33/SUM($B$33:$E$33))*10,(C34/SUM($B$34:$E$34))*10) + 2.17, 2) -> 5.31 | D28: =ROUND(AVERAGE((D29/117)*10,(D30/117)*10,(D31/13)*10,(D32/40)*10,(D33/SUM($B$33:$E$33))*10,(D34/SUM($B$34:$E$34))*10) + 2.17, 2) -> 3.33 | E28: =ROUND(AVERAGE((E29/117)*10,(E30/117)*10,(E31/13)*10,(E32/40)*10,(E33/SUM($B$33:$E$33))*10,(E34/SUM($B$34:$E$34))*10) + 2.17, 2) -> 3.2
A29: Formal Assembly MLAs | B29: 94 | C29: 16 | D29: 3 | E29: 2
A30: Current aligned seats used | B30: 95 | C30: 16 | D30: 1 | E30: 2
A31: 2024 LS seats (diagnostic) | B31: 3 | C31: 7 | D31: 1 | E31: 0
A32: 2024 LS vote share % (diagnostic) | B32: 26.02 | C32: 26.3 | D32: 13.42 | E32: 18.56
A33: 2025 Zila Parishad zones | B33: 218 | C33: 62 | D33: 46 | E33: 7
A34: May 2026 civic wards | B34: 958 | C34: 397 | D34: 192 | E34: 172
A37: Assembly 2017,2022 - Taken as Main LokSabha 2019, 2024 - Mid-term stress testing
A40: Category | B40: Tab Name | C40: Description & Scope
A41: Constituency Analysis | B41: 117 Battles | C41: Comprehensive seat-by-seat classification, challenger scores, and party dynamics across all 117 ACs Seat strength and projections
A42: Constituency Analysis | B42: Top Battlegrounds | C42: Deep dive into the 20 most competitive seats, margins, and key local drivers
A43: Constituency Analysis | B43: Assembly Competitiveness | C43: Assembly Competitiveness Index (ACI), closeness metrics, and margin turbulence
A44: Constituency Analysis | B44: Assembly Volatality | C44: Electoral Volatility Index (AVI), turnover scores, and seat volatility classification
A45: Constituency Analysis | B45: Assembly Trajectories | C45: Historical trajectory comparison across 2017 & 2022 AE vs 2019 & 2024 LS
A46: Strategic Assessment | B46: Party wise Performance | C46: Historical election performance, vote shares, seat shares, and swings
A47: Strategic Assessment | B47: Party Social Coalitions | C47: Social base, caste matrix, and coalition breakdown across major political parties
A48: Strategic Assessment | B48: Political Geography | C48: Regional breakdown across Malwa, Majha, Doaba, Urban, and Rural Punjab
A49: Strategic Assessment | B49: Voter Groups | C49: Key demographic and socio-economic voter segments, concerns, and party alignment
A50: Strategic Assessment | B50: Issues | C50: Salience, severity, and political risk mapping of key state and local issues
...

Sheet Final Assesment
A1: PUNJAB 2027 FINAL ASSESSMENT
A2: EARLY 2027 STRUCTURAL CLASSIFICATION
A3: Party/Force | B3: Classification | C3: Evidence for classification | D3: Structural advantage | E3: Structural disadvantage | F3: What would upgrade classification | G3: What would downgrade classification | H3: Confidence
A4: AAP | B4: Frontrunner (structural) | C4: 94 formal MLAs,strongest recent local-body performance,Mann,welfare and statewide organisation;2024 LS correction secondary. | D4: Incumbency + ground network + largest current Assembly base | E4: High-salience governance burden and coalition erosion; ticket/elite issues | F4: Sustained Assembly polling lead + welfare satisfaction + Malwa retention evidence | G4: Broad anti-incumbency + Congress consolidation + Malwa erosion | H4: Medium-High
A5: INC | B5: Strong Challenger | C5: 16 MLAs,deep candidate/organisation network and current Congress coordination effort;7 MPs/37 LS segments secondary parliamentary evidence. | D5: Broad social/regional acceptability and experienced candidates | E5: Factionalism; only16 MLAs and huge Malwa gap from2022 | F5: Leadership unity + strong Malwa polling/organisation | G5: Factional split/rebels + BJP/SAD/WPD fragment anti-AAP vote | H5: Medium-High
A6: BJP | B6: Competitive / Expanding | C6: 2 MLAs,expanding civic/urban+booth network,new recruits;18.56% LS/23 segments secondary diagnostics. | D6: Largest expansion headroom and national resources | E6: Rural/Sikh/farmer ceiling and vote concentration | F6: Strong rural candidates/polling + Assembly conversion in mixed seats | G6: Rural rejection persists and Centre-farmer/federal issues dominate | H6: Medium
A7: SAD | B7: Recovering Regional Force | C7: 3 formal MLAs but narrower aligned footprint;rural local-body residue,Bathinda/Panthic networks;2024 LS weakness secondary. | D7: Historic cadre/regional identity | E7: 13.42% LS vote, defections, Badal/sacrilege baggage, WPD competition | F7: Vote stabilisation + leader/cadre returns + credible reform/alliance clarity | G7: More defections + WPD scales + rural vote shifts to INC/AAP | H7: Medium
A8: BSP | B8: Regional / Niche Spoiler | C8: Distinct Doaba/social-justice cadre,1 MLA and local organisation;LS evidence secondary. | D8: Ideological/cadre distinctiveness in selected SC-heavy seats | E8: Low recent statewide conversion and heterogeneous Dalit vote | F8: Strong candidates + measurable Doaba vote growth | G8: Continued low single-digit share and tactical shift to larger parties | H8: Medium
A9: WPD / Panthic Independents | B9: Emerging Regional Force / Spoiler | C9: Two independent MPs+Panthic/candidate networks;15 LS segments disruption diagnostic,not statewide AE baseline. | D9: Authentic alternative Panthic/candidate energy | E9: Registration/organisation/scalability and legal/personal constraints | F9: Formal organisation + credible multi-district candidates + issue breadth | G9: Support stays personal/local and factions split | H9: Low-Medium statewide / High local
A15: FINAL PARTY MATRIX
A16: Party | B16: Base | C16: Must Retain | D16: Growth Opportunity | E16: Biggest Threat | F16: Key Region | G16: Key Political Problem | H16: Path to Victory
A17: AAP | B17: Large Assembly/local-body base; 2022 cross-group coalition; welfare; Mann | C17: Malwa + sufficient Doaba/Majha + organisational incumbency | D17: Recover 2024-adverse seats through Assembly reversion/candidate reset; exploit opposition fragmentation | E17: Cross-group anti-incumbency consolidation and multiple local rebellions | F17: Malwa | G17: Convert incumbency from liability into delivery credibility while managing jobs/drugs/farmer/law-order grievances | H17: Contain losses from current94 formal seats, preserve broad-enough coalition and prevent one opposition pole from dominating.
A18: INC | B18: Majha/Doaba parliamentary strength; broad anti-AAP coalition; candidate bench | C18: 2024 MPs/segments, current MLAs, OBC/Dalit/candidate coalition | D18: Large Malwa conversion from AAP-held Assembly-first competitive seats | E18: Factionalism and BJP/SAD/WPD splitting opposition | F18: Malwa | G18: Turn broad but distributed leadership into one campaign and one ticket machine | H18: Retain Majha/Doaba + make major Malwa gains + become principal anti-AAP option.
A19: SAD | B19: Residual rural/Panthic/Jat Sikh cadre and Bathinda-Malwa networks | C19: Existing cadre/pockets and remaining trust | D19: AAP rural dissatisfaction; lower winning thresholds; possible alliance complement | E19: WPD/Panthic fragmentation, Badal legacy, defections and urban loss to BJP | F19: Malwa | G19: Re-establish why SAD is uniquely relevant before asking voters to return | H19: Restore credibility/core, add a non-core/urban leg, rebuild Malwa seat conversion and reduce splinter competition.
A20: BJP | B20: Urban Hindu/trader/MSME core;2024 standalone voters; national resources | C20: Urban core and new recruits | D20: Test whether2024 urban/parliamentary support can be reproduced in Assembly contests through viable local candidates,booths and mixed-seat coalitions. | E20: Rural/Sikh/farmer ceiling; Centre-state/federal liabilities; vote concentration | F20: Urban nodes across all three regions, then rural bridge | G20: Turn a high but concentrated vote into constituency-scale coalitions | H20: Convert urban base → build local candidates/booths → gain enough rural/Sikh credibility → exploit multi-cornered pluralities.
A21: BSP | B21: Doaba cadre/social-justice pockets | C21: Core organisation and viable SC-heavy seats | D21: Selective reserved-seat growth | E21: Low conversion, tactical voting to larger parties | F21: Doaba | G21: Translate distinct identity into credible local candidates, not demographic arithmetic | H21: Build multiple seat wins and broader coalition first; current evidence is not government-scale.
A22: WPD / Emerging | B22: Khadoor/Faridkot/selected Panthic networks; personal mandates | C22: Candidate strongholds and organisational nodes | D22: SAD weakness/Panthic vacuum and high-volatility seats | E22: Personality dependence, registration/scalability, mutual fragmentation | F22: Majha first; selected Malwa area | G22: Build an organisation and governance proposition larger than individual leaders | H22: Formalise → field credible multi-seat slate → broaden beyond Panthic protest; government-scale path remains unproven.
A29: No. | B29: DATA | C29: TREND | D29: WHY | E29: WHO / WHERE | F29: ELECTORAL IMPACT | G29: 2027 IMPLICATION
A30: 1 | B30: AAP:92 Assembly seats in2022; only33 LS-segment leads in2024; then strong2025/26 local-body performance. | C30: AAP's coalition weakened at parliamentary level but organisation did not collapse. | D30: 2022 was a broad change wave;2024 fragmented that coalition across INC/BJP/IND/SAD, while sub-state incumbency networks remained intact. | E30: Malwa AAP base; Majha warning; Doaba competitive; welfare/local-office-holder networks statewide. | F30: LS swing cannot be directly projected onto Assembly seats. | G30: The key AAP question is coalition retention and Assembly-vs-LS reversion-not whether2024 erased2022.
A31: 2 | B31: INC:77 seats2017 →18 in2022 →7 MPs/37 LS-segment leads2024. | C31: Congress can collapse and recover quickly because its support is broad but leadership/candidate dependent. | D31: Amarinder anchored2017/19; factional churn hurt2022; strong candidates and broad social acceptability aided2024. | E31: Majha/Doaba strongest; Malwa is growth frontier. | F31: Congress has the clearest opposition government path but also the largest organisational conversion challenge. | G31: Watch unity and Malwa seat-level organisation more than national/statewide vote share alone.
A32: 3 | B32: Malwa contains69/117 seats; AAP won66 in2022 but led24 LS segments2024. | C32: Punjab's largest region moved from AAP near-monopoly to multi-party fragmentation. | D32: Mann/change/farm-youth coalition drove2022; Congress/SAD/BJP/IND regained different pockets in2024. | E32: Rural farmer/labour/youth seats plus Ludhiana/Bathinda/Abohar urban-industrial nodes. | F32: A small regional movement can change dozens of Assembly seats. | G32: No party forms a stable majority coalition without a serious Malwa strategy.
A33: 4 | B33: Majha2024 LS segments: INC10, BJP6, IND6, AAP2, SAD1. | C33: Majha is the most politically fragmented region. | D33: Border/security, Panthic politics, farm issues, urban Hindu pockets and candidate networks activate differently by election type. | E33: Amritsar-Gurdaspur-Tarn Taran/Pathankot belt. | F33: Statewide swings can break into four/five different local contests here. | G33: Majha is the best stress-test for any claim of a simple statewide wave.
A34: 5 | B34: Assembly:AAP23.72%2017→42.01%2022. Parliamentary diagnostic:7.38%2019→26.02%2024. | C34: Election-type movement can differ radically. | D34: 2019 weak AAP LS preceded2022 Assembly landslide;2024 therefore cannot be read as2027 seat map. | E34: Statewide;especially AAP-held seats where2024 differed. | F34: LS identifies coalition stress,not Assembly vulnerability by itself. | G34: Build2027 from2022/current Assembly evidence,then use2024 to ask where coalition stressed.
A35: 6 | B35: Assembly:SAD25.24%2017→18.38%2022. Parliamentary diagnostic:27.45%2019→13.42%2024; rural local-body footprint persists. | C35: SAD weakened in both election types but organisation has not disappeared. | D35: Assembly decline,credibility costs,lost BJP complement and Panthic fragmentation. | E35: Bathinda-Malwa rural/Panthic pockets. | F35: Can affect close seats without statewide-power scale. | G35: Track Assembly/current cadre conversion and WPD competition.
A36: 7 | B36: Assembly:BJP5.39%2017→6.60%2022. Parliamentary diagnostic:9.63%2019 alliance-limited→18.56%2024 standalone. | C36: Parliamentary expansion faster than Assembly conversion. | D36: Alliance structure changed and support remains urban/semiurban concentrated. | E36: Urban nodes across three regions. | F36: High LS vote can yield few MLAs if candidates/rural reach weak. | G36: Measure Assembly viability through runner-up position,ACI/AVI,civic/booth strength and rural bridge.
A37: 8 | B37: Two independent MPs +15 independent-led LS segments in2024; WPD later gained Ayali and district/youth structures. | C37: Panthic protest now has an electoral channel outside SAD. | D37: SAD credibility crisis created a vacuum; charismatic candidates converted it locally. | E37: Khadoor/Tarn Taran/Faridkot and selected Malwa. | F37: Emerging candidates can change margins and issue salience even with limited statewide organisation. | G37: The question is scalability: candidate mandates must become booths, candidates and a broader governance agenda.
A38: 9 | B38: Youth unemployment22.3% Apr-Jun2026; migration widespread; drugs/farmer/law-order remain high salience; AAP welfare remains large. | C38: 2027 can simultaneously contain anti-incumbency and beneficiary retention. | D38: Households evaluate multiple issues; Centre/state blame is split; material welfare can coexist with dissatisfaction. | E38: Youth, farm households, women, employees, urban business and migration-linked families statewide. | F38: No single issue guarantees a uniform swing; issue mix determines which coalition component moves. | G38: War room should track issue attribution and beneficiary satisfaction, not just issue importance.
A39: 10 | B39: Revised Phase5 model now weights 2022 Assembly/current Assembly evidence far above 2019/2024 Lok Sabha signals. | C39: Seat intelligence shifts from four-election chronology to election-type relevance. | D39: 2019 showed that a weak LS result can be followed by an Assembly landslide; 2024 is better interpreted as coalition fragmentation/stress rather than an Assembly seat map. | E39: All117 seats, especially AAP-held seats where 2024 LS pointed elsewhere. | F39: Candidate, incumbency, organisation and Assembly-specific voter return become more important than parliamentary segment leads. | G39: Use 2019 for history, 2024 for coalition stress, and build the 2027 battlefield primarily from 2022 Assembly + current organisation/issues + recent Assembly tests.

Sheet 117 Battles 
A1: 2027 BATTLEFIELD MAP
A2: What each category means: Stronghold: Safe, dominant seat. The incumbent party has won consistently with wide margins and low competition. Lean: Incumbent holds an advantage, with low-to-moderate competition and steady support. Battleground: Evenly balanced contest / toss-up where neither party has a clear structural buffer. Opposition Lean: The incumbent is under severe pressure; the primary challenger has won multiple recent elections here. Highly Volatile: Unstable seat with frequent party turnovers across election cycles or sharp voter swings. Example: Sujanpur Result: Opposition Lean (Incumbent INC faces strong challenger BJP, who won the 2017 Assembly and 2024 Lok Sabha segment).
A3: AC | B3: Seat | C3: District | D3: Region | E3: Current incumbent | F3: Classification | G3: Current | H3: 2017 AE | I3: 2022 AE | J3: 2019 LS Historical | K3: 2024 LS Diagnostic | L3: Recent Assembly Update | M3: 2022 Runner-up | N3: 2022 Margin% | O3: ACI | P3: AVI | Q3: Combined | R3: Primary Challenger | S3: 2024 Stress? | T3: AAP | U3: INC | V3: SAD | W3: BJP | X3: Multi-cornered
A4: 1 | B4: Sujanpur | C4: Pathankot | D4: Majha | E4: Naresh Puri | F4: =IFS(OR(P4>=75, ((H4<>J4)+(J4<>I4)+(I4<>K4))>=3), "Highly Volatile", AND(COUNTIF(H4:K4, G4)+1>=4, O4<55, P4<65), "Stronghold", AND(COUNTIF(H4:K4, G4)+1>=3, O4<70, P4<75), "Lean", AND(R4<>G4, ((H4=R4)+(J4=R4)+(K4=R4))>=2, O4<60, P4<70), "Opposition Lean", TRUE, "Battleground") -> Opposition Lean | G4: INC | H4: BJP | I4: INC | J4: BJP | K4: BJP | M4: BJP | N4: 3.61 | O4: {=_xlfn.XLOOKUP(B4, 'Assembly Competitiveness'!$B$4:$B$120,'Assembly Competitiveness'!$O$4:$O$120, "-")} -> 56.4095 | P4: {=_xlfn.XLOOKUP(B4,'Assembly Volatality'!$B$4:$B$120,'Assembly Volatality'!$L$4:$L$120, "-")} -> 53.7 | Q4: =ROUND(0.45*O4+0.4*P4+0.15*IF(H4<>K4,100,0),1) -> 46.9 | R4: BJP | S4: YES | T4: =IFS( AND(G4="AAP", OR(F4="Stronghold", F4="Lean")), "Defend", OR( AND(G4="AAP", OR(F4="Battleground", F4="Highly Volatile", F4="Opposition Lean")), AND(R4="AAP", OR(F4="Battleground", F4="Highly Volatile", F4="Opposition Lean")) ), "Battleground", OR(K4="AAP", M4="AAP", R4="AAP"), "Expand", TRUE, "Long Shot" ) -> Long Shot | U4: =IFS( AND(G4="INC", OR(F4="Stronghold", F4="Lean")), "Defend", OR( AND(G4="INC", OR(F4="Battleground", F4="Highly Volatile", F4="Opposition Lean")), AND(R4="INC", OR(F4="Battleground", F4="Highly Volatile", F4="Opposition Lean")) ), "Battleground", OR(K4="INC", M4="INC", R4="INC"), "Expand", TRUE, "Long Shot" ) -> Battleground | V4: =IFS( AND(G4="SAD", OR(F4="Stronghold", F4="Lean")), "Defend", OR( AND(G4="SAD", OR(F4="Battleground", F4="Highly Volatile", F4="Opposition Lean")), AND(R4="SAD", OR(F4="Battleground", F4="Highly Volatile", F4="Opposition Lean")) ), "Battleground", OR(K4="SAD", M4="SAD", R4="SAD"), "Expand", TRUE, "Long Shot" ) -> Long Shot | W4: =IFS( AND(G4="BJP", OR(F4="Stronghold", F4="Lean")), "Defend", OR( AND(G4="BJP", OR(F4="Battleground", F4="Highly Volatile", F4="Opposition Lean")), AND(R4="BJP", OR(F4="Battleground", F4="Highly Volatile", F4="Opposition Lean")) ), "Battleground", OR(K4="BJP", M4="BJP", R4="BJP"), "Expand", TRUE, "Long Shot" ) -> Battleground | X4: =IFS(K4="EMERGING", "YES", COUNTIFS(T4:W4, "<>Long Shot", T4:W4, "<>") >= 3, "YES", TRUE, "")
A5: 2 | B5: Bhoa | C5: Pathankot | D5: Majha | E5: Lal Chand | F5: =IFS( OR(P5>=75, ((H5<>J5)+(J5<>I5)+(I5<>K5))>=3), "Highly Volatile", AND(COUNTIF(H5:K5, G5)+1>=4, O5<55, P5<65), "Stronghold", AND(COUNTIF(H5:K5, G5)+1>=3, O5<70, P5<75), "Lean", AND(R5<>G5, ((H5=R5)+(J5=R5)+(K5=R5))>=2, O5<60, P5<70), "Opposition Lean", TRUE, "Battleground" ) -> Highly Volatile | G5: AAP | H5: INC | I5: AAP | J5: BJP | K5: BJP | M5: INC | N5: 0.88 | O5: {=_xlfn.XLOOKUP(B5, 'Assembly Competitiveness'!$B$4:$B$120,'Assembly Competitiveness'!$O$4:$O$120, "-")} -> 61.088 | P5: {=_xlfn.XLOOKUP(B5,'Assembly Volatality'!$B$4:$B$120,'Assembly Volatality'!$L$4:$L$120, "-")} -> 61.5 | Q5: =ROUND(0.45*O5+0.4*P5+0.15*IF(H5<>K5,100,0),1) -> 67.1 | R5: INC | S5: YES | T5: =IFS( AND(G5="AAP", OR(F5="Stronghold", F5="Lean")), "Defend", OR( AND(G5="AAP", OR(F5="Battleground", F5="Highly Volatile", F5="Opposition Lean")), AND(R5="AAP", OR(F5="Battleground", F5="Highly Volatile", F5="Opposition Lean")) ), "Battleground", OR(K5="AAP", M5="AAP", R5="AAP"), "Expand", TRUE, "Long Shot" ) -> Battleground | U5: =IFS( AND(G5="INC", OR(F5="Stronghold", F5="Lean")), "Defend", OR( AND(G5="INC", OR(F5="Battleground", F5="Highly Volatile", F5="Opposition Lean")), AND(R5="INC", OR(F5="Battleground", F5="Highly Volatile", F5="Opposition Lean")) ), "Battleground", OR(K5="INC", M5="INC", R5="INC"), "Expand", TRUE, "Long Shot" ) -> Battleground | V5: =IFS( AND(G5="SAD", OR(F5="Stronghold", F5="Lean")), "Defend", OR( AND(G5="SAD", OR(F5="Battleground", F5="Highly Volatile", F5="Opposition Lean")), AND(R5="SAD", OR(F5="Battleground", F5="Highly Volatile", F5="Opposition Lean")) ), "Battleground", OR(K5="SAD", M5="SAD", R5="SAD"), "Expand", TRUE, "Long Shot" ) -> Long Shot | W5: =IFS( AND(G5="BJP", OR(F5="Stronghold", F5="Lean")), "Defend", OR( AND(G5="BJP", OR(F5="Battleground", F5="Highly Volatile", F5="Opposition Lean")), AND(R5="BJP", OR(F5="Battleground", F5="Highly Volatile", F5="Opposition Lean")) ), "Battleground", OR(K5="BJP", M5="BJP", R5="BJP"), "Expand", TRUE, "Long Shot" ) -> Expand | X5: =IFS(K5="EMERGING", "YES", COUNTIFS(T5:W5, "<>Long Shot", T5:W5, "<>") >= 3, "YES", TRUE, "") -> YES
A6: 3 | B6: Pathankot | C6: Pathankot | D6: Majha | E6: Ashwani Kumar Sharma | F6: =IFS( OR(P6>=75, ((H6<>J6)+(J6<>I6)+(I6<>K6))>=3), "Highly Volatile", AND(COUNTIF(H6:K6, G6)+1>=4, O6<55, P6<65), "Stronghold", AND(COUNTIF(H6:K6, G6)+1>=3, O6<70, P6<75), "Lean", AND(R6<>G6, ((H6=R6)+(J6=R6)+(K6=R6))>=2, O6<60, P6<70), "Opposition Lean", TRUE, "Battleground" ) -> Stronghold | G6: BJP | H6: INC | I6: BJP | J6: BJP | K6: BJP | M6: INC | N6: 6.88 | O6: {=_xlfn.XLOOKUP(B6, 'Assembly Competitiveness'!$B$4:$B$120,'Assembly Competitiveness'!$O$4:$O$120, "-")} -> 40.672 | P6: {=_xlfn.XLOOKUP(B6,'Assembly Volatality'!$B$4:$B$120,'Assembly Volatality'!$L$4:$L$120, "-")} -> 34.97 | Q6: =ROUND(0.45*O6+0.4*P6+0.15*IF(H6<>K6,100,0),1) -> 47.3 | R6: INC | T6: =IFS(AND(G6="AAP", OR(F6="Stronghold", F6="Lean")), "Defend", OR( AND(G6="AAP", OR(F6="Battleground", F6="Highly Volatile", F6="Opposition Lean")),AND(R6="AAP", OR(F6="Battleground", F6="Highly Volatile", F6="Opposition Lean"))), "Battleground", OR(K6="AAP", M6="AAP", R6="AAP"), "Expand", TRUE, "Long Shot") -> Long Shot | U6: =IFS( AND(G6="INC", OR(F6="Stronghold", F6="Lean")), "Defend", OR( AND(G6="INC", OR(F6="Battleground", F6="Highly Volatile", F6="Opposition Lean")), AND(R6="INC", OR(F6="Battleground", F6="Highly Volatile", F6="Opposition Lean")) ), "Battleground", OR(K6="INC", M6="INC", R6="INC"), "Expand", TRUE, "Long Shot" ) -> Expand | V6: =IFS( AND(G6="SAD", OR(F6="Stronghold", F6="Lean")), "Defend", OR( AND(G6="SAD", OR(F6="Battleground", F6="Highly Volatile", F6="Opposition Lean")), AND(R6="SAD", OR(F6="Battleground", F6="Highly Volatile", F6="Opposition Lean")) ), "Battleground", OR(K6="SAD", M6="SAD", R6="SAD"), "Expand", TRUE, "Long Shot" ) -> Long Shot | W6: =IFS( AND(G6="BJP", OR(F6="Stronghold", F6="Lean")), "Defend", OR( AND(G6="BJP", OR(F6="Battleground", F6="Highly Volatile", F6="Opposition Lean")), AND(R6="BJP", OR(F6="Battleground", F6="Highly Volatile", F6="Opposition Lean")) ), "Battleground", OR(K6="BJP", M6="BJP", R6="BJP"), "Expand", TRUE, "Long Shot" ) -> Defend | X6: =IFS(K6="EMERGING", "YES", COUNTIFS(T6:W6, "<>Long Shot", T6:W6, "<>") >= 3, "YES", TRUE, "")
A7: 4 | B7: Gurdaspur | C7: Gurdaspur | D7: Majha | E7: Barindermeet Singh Pahra | F7: =IFS( OR(P7>=75, ((H7<>J7)+(J7<>I7)+(I7<>K7))>=3), "Highly Volatile", AND(COUNTIF(H7:K7, G7)+1>=4, O7<55, P7<65), "Stronghold", AND(COUNTIF(H7:K7, G7)+1>=3, O7<70, P7<75), "Lean", AND(R7<>G7, ((H7=R7)+(J7=R7)+(K7=R7))>=2, O7<60, P7<70), "Opposition Lean", TRUE, "Battleground" ) -> Stronghold | G7: INC | H7: INC | I7: INC | J7: BJP | K7: INC | M7: SAD | N7: 5.94 | O7: {=_xlfn.XLOOKUP(B7, 'Assembly Competitiveness'!$B$4:$B$120,'Assembly Competitiveness'!$O$4:$O$120, "-")} -> 39.175 | P7: {=_xlfn.XLOOKUP(B7,'Assembly Volatality'!$B$4:$B$120,'Assembly Volatality'!$L$4:$L$120, "-")} -> 21.72 | Q7: =ROUND(0.45*O7+0.4*P7+0.15*IF(H7<>K7,100,0),1) -> 26.3 | R7: SAD | T7: =IFS( AND(G7="AAP", OR(F7="Stronghold", F7="Lean")), "Defend", OR( AND(G7="AAP", OR(F7="Battleground", F7="Highly Volatile", F7="Opposition Lean")), AND(R7="AAP", OR(F7="Battleground", F7="Highly Volatile", F7="Opposition Lean")) ), "Battleground", OR(K7="AAP", M7="AAP", R7="AAP"), "Expand", TRUE, "Long Shot" ) -> Long Shot | U7: =IFS( AND(G7="INC", OR(F7="Stronghold", F7="Lean")), "Defend", OR( AND(G7="INC", OR(F7="Battleground", F7="Highly Volatile", F7="Opposition Lean")), AND(R7="INC", OR(F7="Battleground", F7="Highly Volatile", F7="Opposition Lean")) ), "Battleground", OR(K7="INC", M7="INC", R7="INC"), "Expand", TRUE, "Long Shot" ) -> Defend | V7: =IFS( AND(G7="SAD", OR(F7="Stronghold", F7="Lean")), "Defend", OR( AND(G7="SAD", OR(F7="Battleground", F7="Highly Volatile", F7="Opposition Lean")), AND(R7="SAD", OR(F7="Battleground", F7="Highly Volatile", F7="Opposition Lean")) ), "Battleground", OR(K7="SAD", M7="SAD", R7="SAD"), "Expand", TRUE, "Long Shot" ) -> Expand | W7: =IFS( AND(G7="BJP", OR(F7="Stronghold", F7="Lean")), "Defend", OR( AND(G7="BJP", OR(F7="Battleground", F7="Highly Volatile", F7="Opposition Lean")), AND(R7="BJP", OR(F7="Battleground", F7="Highly Volatile", F7="Opposition Lean")) ), "Battleground", OR(K7="BJP", M7="BJP", R7="BJP"), "Expand", TRUE, "Long Shot" ) -> Long Shot | X7: =IFS(K7="EMERGING", "YES", COUNTIFS(T7:W7, "<>Long Shot", T7:W7, "<>") >= 3, "YES", TRUE, "")
A8: 5 | B8: Dina Nagar | C8: Gurdaspur | D8: Majha | E8: Aruna Chaudhary | F8: =IFS( OR(P8>=75, ((H8<>J8)+(J8<>I8)+(I8<>K8))>=3), "Highly Volatile", AND(COUNTIF(H8:K8, G8)+1>=4, O8<55, P8<65), "Stronghold", AND(COUNTIF(H8:K8, G8)+1>=3, O8<70, P8<75), "Lean", AND(R8<>G8, ((H8=R8)+(J8=R8)+(K8=R8))>=2, O8<60, P8<70), "Opposition Lean", TRUE, "Battleground" ) -> Stronghold | G8: INC | H8: INC | I8: INC | J8: BJP | K8: INC | M8: AAP | N8: 0.81 | O8: {=_xlfn.XLOOKUP(B8, 'Assembly Competitiveness'!$B$4:$B$120,'Assembly Competitiveness'!$O$4:$O$120, "-")} -> 52.7295 | P8: {=_xlfn.XLOOKUP(B8,'Assembly Volatality'!$B$4:$B$120,'Assembly Volatality'!$L$4:$L$120, "-")} -> 23.98 | Q8: =ROUND(0.45*O8+0.4*P8+0.15*IF(H8<>K8,100,0),1) -> 33.3 | R8: AAP | T8: =IFS( AND(G8="AAP", OR(F8="Stronghold", F8="Lean")), "Defend", OR( AND(G8="AAP", OR(F8="Battleground", F8="Highly Volatile", F8="Opposition Lean")), AND(R8="AAP", OR(F8="Battleground", F8="Highly Volatile", F8="Opposition Lean")) ), "Battleground", OR(K8="AAP", M8="AAP", R8="AAP"), "Expand", TRUE, "Long Shot" ) -> Expand | U8: =IFS( AND(G8="INC", OR(F8="Stronghold", F8="Lean")), "Defend", OR( AND(G8="INC", OR(F8="Battleground", F8="Highly Volatile", F8="Opposition Lean")), AND(R8="INC", OR(F8="Battleground", F8="Highly Volatile", F8="Opposition Lean")) ), "Battleground", OR(K8="INC", M8="INC", R8="INC"), "Expand", TRUE, "Long Shot" ) -> Defend | V8: =IFS( AND(G8="SAD", OR(F8="Stronghold", F8="Lean")), "Defend", OR( AND(G8="SAD", OR(F8="Battleground", F8="Highly Volatile", F8="Opposition Lean")), AND(R8="SAD", OR(F8="Battleground", F8="Highly Volatile", F8="Opposition Lean")) ), "Battleground", OR(K8="SAD", M8="SAD", R8="SAD"), "Expand", TRUE, "Long Shot" ) -> Long Shot | W8: =IFS( AND(G8="BJP", OR(F8="Stronghold", F8="Lean")), "Defend", OR( AND(G8="BJP", OR(F8="Battleground", F8="Highly Volatile", F8="Opposition Lean")), AND(R8="BJP", OR(F8="Battleground", F8="Highly Volatile", F8="Opposition Lean")) ), "Battleground", OR(K8="BJP", M8="BJP", R8="BJP"), "Expand", TRUE, "Long Shot" ) -> Long Shot | X8: =IFS(K8="EMERGING", "YES", COUNTIFS(T8:W8, "<>Long Shot", T8:W8, "<>") >= 3, "YES", TRUE, "")
A9: 6 | B9: Qadian | C9: Gurdaspur | D9: Majha | E9: Partap Singh Bajwa | F9: =IFS( OR(P9>=75, ((H9<>J9)+(J9<>I9)+(I9<>K9))>=3), "Highly Volatile", AND(COUNTIF(H9:K9, G9)+1>=4, O9<55, P9<65), "Stronghold", AND(COUNTIF(H9:K9, G9)+1>=3, O9<70, P9<75), "Lean", AND(R9<>G9, ((H9=R9)+(J9=R9)+(K9=R9))>=2, O9<60, P9<70), "Opposition Lean", TRUE, "Battleground" ) -> Stronghold | G9: INC | H9: INC | I9: INC | J9: BJP | K9: INC | M9: SAD | N9: 5.42 | O9: {=_xlfn.XLOOKUP(B9, 'Assembly Competitiveness'!$B$4:$B$120,'Assembly Competitiveness'!$O$4:$O$120, "-")} -> 45.255 | P9: {=_xlfn.XLOOKUP(B9,'Assembly Volatality'!$B$4:$B$120,'Assembly Volatality'!$L$4:$L$120, "-")} -> 5.61 | Q9: =ROUND(0.45*O9+0.4*P9+0.15*IF(H9<>K9,100,0),1) -> 22.6 | R9: SAD | T9: =IFS( AND(G9="AAP", OR(F9="Stronghold", F9="Lean")), "Defend", OR( AND(G9="AAP", OR(F9="Battleground", F9="Highly Volatile", F9="Opposition Lean")), AND(R9="AAP", OR(F9="Battleground", F9="Highly Volatile", F9="Opposition Lean")) ), "Battleground", OR(K9="AAP", M9="AAP", R9="AAP"), "Expand", TRUE, "Long Shot" ) -> Long Shot | U9: =IFS( AND(G9="INC", OR(F9="Stronghold", F9="Lean")), "Defend", OR( AND(G9="INC", OR(F9="Battleground", F9="Highly Volatile", F9="Opposition Lean")), AND(R9="INC", OR(F9="Battleground", F9="Highly Volatile", F9="Opposition Lean")) ), "Battleground", OR(K9="INC", M9="INC", R9="INC"), "Expand", TRUE, "Long Shot" ) -> Defend | V9: =IFS( AND(G9="SAD", OR(F9="Stronghold", F9="Lean")), "Defend", OR( AND(G9="SAD", OR(F9="Battleground", F9="Highly Volatile", F9="Opposition Lean")), AND(R9="SAD", OR(F9="Battleground", F9="Highly Volatile", F9="Opposition Lean")) ), "Battleground", OR(K9="SAD", M9="SAD", R9="SAD"), "Expand", TRUE, "Long Shot" ) -> Expand | W9: =IFS( AND(G9="BJP", OR(F9="Stronghold", F9="Lean")), "Defend", OR( AND(G9="BJP", OR(F9="Battleground", F9="Highly Volatile", F9="Opposition Lean")), AND(R9="BJP", OR(F9="Battleground", F9="Highly Volatile", F9="Opposition Lean")) ), "Battleground", OR(K9="BJP", M9="BJP", R9="BJP"), "Expand", TRUE, "Long Shot" ) -> Long Shot | X9: =IFS(K9="EMERGING", "YES", COUNTIFS(T9:W9, "<>Long Shot", T9:W9, "<>") >= 3, "YES", TRUE, "")
A10: 7 | B10: Batala | C10: Gurdaspur | D10: Majha | E10: Amansher Singh (Shery Kalsi) | F10: =IFS( OR(P10>=75, ((H10<>J10)+(J10<>I10)+(I10<>K10))>=3), "Highly Volatile", AND(COUNTIF(H10:K10, G10)+1>=4, O10<55, P10<65), "Stronghold", AND(COUNTIF(H10:K10, G10)+1>=3, O10<70, P10<75), "Lean", AND(R10<>G10, ((H10=R10)+(J10=R10)+(K10=R10))>=2, O10<60, P10<70), "Opposition Lean", TRUE, "Battleground" ) -> Highly Volatile | G10: AAP | H10: SAD | I10: AAP | J10: BJP | K10: INC | M10: INC | N10: 22.44 | O10: {=_xlfn.XLOOKUP(B10, 'Assembly Competitiveness'!$B$4:$B$120,'Assembly Competitiveness'!$O$4:$O$120, "-")} -> 38.416 | P10: {=_xlfn.XLOOKUP(B10,'Assembly Volatality'!$B$4:$B$120,'Assembly Volatality'!$L$4:$L$120, "-")} -> 64.25 | Q10: =ROUND(0.45*O10+0.4*P10+0.15*IF(H10<>K10,100,0),1) -> 58 | R10: INC | S10: YES | T10: =IFS( AND(G10="AAP", OR(F10="Stronghold", F10="Lean")), "Defend", OR( AND(G10="AAP", OR(F10="Battleground", F10="Highly Volatile", F10="Opposition Lean")), AND(R10="AAP", OR(F10="Battleground", F10="Highly Volatile", F10="Opposition Lean")) ), "Battleground", OR(K10="AAP", M10="AAP", R10="AAP"), "Expand", TRUE, "Long Shot" ) -> Battleground | U10: =IFS( AND(G10="INC", OR(F10="Stronghold", F10="Lean")), "Defend", OR( AND(G10="INC", OR(F10="Battleground", F10="Highly Volatile", F10="Opposition Lean")), AND(R10="INC", OR(F10="Battleground", F10="Highly Volatile", F10="Opposition Lean")) ), "Battleground", OR(K10="INC", M10="INC", R10="INC"), "Expand", TRUE, "Long Shot" ) -> Battleground | V10: =IFS( AND(G10="SAD", OR(F10="Stronghold", F10="Lean")), "Defend", OR( AND(G10="SAD", OR(F10="Battleground", F10="Highly Volatile", F10="Opposition Lean")), AND(R10="SAD", OR(F10="Battleground", F10="Highly Volatile", F10="Opposition Lean")) ), "Battleground", OR(K10="SAD", M10="SAD", R10="SAD"), "Expand", TRUE, "Long Shot" ) -> Long Shot | W10: =IFS( AND(G10="BJP", OR(F10="Stronghold", F10="Lean")), "Defend", OR( AND(G10="BJP", OR(F10="Battleground", F10="Highly Volatile", F10="Opposition Lean")), AND(R10="BJP", OR(F10="Battleground", F10="Highly Volatile", F10="Opposition Lean")) ), "Battleground", OR(K10="BJP", M10="BJP", R10="BJP"), "Expand", TRUE, "Long Shot" ) -> Long Shot | X10: =IFS(K10="EMERGING", "YES", COUNTIFS(T10:W10, "<>Long Shot", T10:W10, "<>") >= 3, "YES", TRUE, "")
A11: 8 | B11: Sri Hargobindpur | C11: Gurdaspur | D11: Majha | E11: Amarpal Singh | F11: =IFS( OR(P11>=75, ((H11<>J11)+(J11<>I11)+(I11<>K11))>=3), "Highly Volatile", AND(COUNTIF(H11:K11, G11)+1>=4, O11<55, P11<65), "Stronghold", AND(COUNTIF(H11:K11, G11)+1>=3, O11<70, P11<75), "Lean", AND(R11<>G11, ((H11=R11)+(J11=R11)+(K11=R11))>=2, O11<60, P11<70), "Opposition Lean", TRUE, "Battleground" ) -> Battleground | G11: AAP | H11: INC | I11: AAP | J11: INC | K11: INC | M11: SAD | N11: 13.78 | O11: {=_xlfn.XLOOKUP(B11, 'Assembly Competitiveness'!$B$4:$B$120,'Assembly Competitiveness'!$O$4:$O$120, "-")} -> 29.723 | P11: {=_xlfn.XLOOKUP(B11,'Assembly Volatality'!$B$4:$B$120,'Assembly Volatality'!$L$4:$L$120, "-")} -> 44.69 | Q11: =ROUND(0.45*O11+0.4*P11+0.15*IF(H11<>K11,100,0),1) -> 31.3 | R11: SAD | S11: YES | T11: =IFS( AND(G11="AAP", OR(F11="Stronghold", F11="Lean")), "Defend", OR( AND(G11="AAP", OR(F11="Battleground", F11="Highly Volatile", F11="Opposition Lean")), AND(R11="AAP", OR(F11="Battleground", F11="Highly Volatile", F11="Opposition Lean")) ), "Battleground", OR(K11="AAP", M11="AAP", R11="AAP"), "Expand", TRUE, "Long Shot" ) -> Battleground | U11: =IFS( AND(G11="INC", OR(F11="Stronghold", F11="Lean")), "Defend", OR( AND(G11="INC", OR(F11="Battleground", F11="Highly Volatile", F11="Opposition Lean")), AND(R11="INC", OR(F11="Battleground", F11="Highly Volatile", F11="Opposition Lean")) ), "Battleground", OR(K11="INC", M11="INC", R11="INC"), "Expand", TRUE, "Long Shot" ) -> Expand | V11: =IFS( AND(G11="SAD", OR(F11="Stronghold", F11="Lean")), "Defend", OR( AND(G11="SAD", OR(F11="Battleground", F11="Highly Volatile", F11="Opposition Lean")), AND(R11="SAD", OR(F11="Battleground", F11="Highly Volatile", F11="Opposition Lean")) ), "Battleground", OR(K11="SAD", M11="SAD", R11="SAD"), "Expand", TRUE, "Long Shot" ) -> Battleground | W11: =IFS( AND(G11="BJP", OR(F11="Stronghold", F11="Lean")), "Defend", OR( AND(G11="BJP", OR(F11="Battleground", F11="Highly Volatile", F11="Opposition Lean")), AND(R11="BJP", OR(F11="Battleground", F11="Highly Volatile", F11="Opposition Lean")) ), "Battleground", OR(K11="BJP", M11="BJP", R11="BJP"), "Expand", TRUE, "Long Shot" ) -> Long Shot | X11: =IFS(K11="EMERGING", "YES", COUNTIFS(T11:W11, "<>Long Shot", T11:W11, "<>") >= 3, "YES", TRUE, "") -> YES
A12: 9 | B12: Fatehgarh Churian | C12: Gurdaspur | D12: Majha | E12: Tript Rajinder Singh Bajwa | F12: =IFS( OR(P12>=75, ((H12<>J12)+(J12<>I12)+(I12<>K12))>=3), "Highly Volatile", AND(COUNTIF(H12:K12, G12)+1>=4, O12<55, P12<65), "Stronghold", AND(COUNTIF(H12:K12, G12)+1>=3, O12<70, P12<75), "Lean", AND(R12<>G12, ((H12=R12)+(J12=R12)+(K12=R12))>=2, O12<60, P12<70), "Opposition Lean", TRUE, "Battleground" ) -> Stronghold | G12: INC | H12: INC | I12: INC | J12: INC | K12: INC | M12: SAD | N12: 4.33 | O12: {=_xlfn.XLOOKUP(B12, 'Assembly Competitiveness'!$B$4:$B$120,'Assembly Competitiveness'!$O$4:$O$120, "-")} -> 54.7215 | P12: {=_xlfn.XLOOKUP(B12,'Assembly Volatality'!$B$4:$B$120,'Assembly Volatality'!$L$4:$L$120, "-")} -> 5.02 | Q12: =ROUND(0.45*O12+0.4*P12+0.15*IF(H12<>K12,100,0),1) -> 26.6 | R12: SAD | T12: =IFS( AND(G12="AAP", OR(F12="Stronghold", F12="Lean")), "Defend", OR( AND(G12="AAP", OR(F12="Battleground", F12="Highly Volatile", F12="Opposition Lean")), AND(R12="AAP", OR(F12="Battleground", F12="Highly Volatile", F12="Opposition Lean")) ), "Battleground", OR(K12="AAP", M12="AAP", R12="AAP"), "Expand", TRUE, "Long Shot" ) -> Long Shot | U12: =IFS( AND(G12="INC", OR(F12="Stronghold", F12="Lean")), "Defend", OR( AND(G12="INC", OR(F12="Battleground", F12="Highly Volatile", F12="Opposition Lean")), AND(R12="INC", OR(F12="Battleground", F12="Highly Volatile", F12="Opposition Lean")) ), "Battleground", OR(K12="INC", M12="INC", R12="INC"), "Expand", TRUE, "Long Shot" ) -> Defend | V12: =IFS( AND(G12="SAD", OR(F12="Stronghold", F12="Lean")), "Defend", OR( AND(G12="SAD", OR(F12="Battleground", F12="Highly Volatile", F12="Opposition Lean")), AND(R12="SAD", OR(F12="Battleground", F12="Highly Volatile", F12="Opposition Lean")) ), "Battleground", OR(K12="SAD", M12="SAD", R12="SAD"), "Expand", TRUE, "Long Shot" ) -> Expand | W12: =IFS( AND(G12="BJP", OR(F12="Stronghold", F12="Lean")), "Defend", OR( AND(G12="BJP", OR(F12="Battleground", F12="Highly Volatile", F12="Opposition Lean")), AND(R12="BJP", OR(F12="Battleground", F12="Highly Volatile", F12="Opposition Lean")) ), "Battleground", OR(K12="BJP", M12="BJP", R12="BJP"), "Expand", TRUE, "Long Shot" ) -> Long Shot | X12: =IFS(K12="EMERGING", "YES", COUNTIFS(T12:W12, "<>Long Shot", T12:W12, "<>") >= 3, "YES", TRUE, "")
A13: 10 | B13: Dera Baba Nanak | C13: Gurdaspur | D13: Majha | E13: Gurdeep Singh Randhawa | F13: =IFS( OR(P13>=75, ((H13<>J13)+(J13<>I13)+(I13<>K13))>=3), "Highly Volatile", AND(COUNTIF(H13:K13, G13)+1>=4, O13<55, P13<65), "Stronghold", AND(COUNTIF(H13:K13, G13)+1>=3, O13<70, P13<75), "Lean", AND(R13<>G13, ((H13=R13)+(J13=R13)+(K13=R13))>=2, O13<60, P13<70), "Opposition Lean", TRUE, "Battleground" ) -> Battleground | G13: AAP | H13: INC | I13: INC | J13: INC | K13: INC | L13: 2024 bypoll AAP gain from INC | M13: SAD | N13: 0.33 | O13: {=_xlfn.XLOOKUP(B13, 'Assembly Competitiveness'!$B$4:$B$120,'Assembly Competitiveness'!$O$4:$O$120, "-")} -> 78.6155 | P13: {=_xlfn.XLOOKUP(B13,'Assembly Volatality'!$B$4:$B$120,'Assembly Volatality'!$L$4:$L$120, "-")} -> 28.76 | Q13: =ROUND(0.45*O13+0.4*P13+0.15*IF(H13<>L13,100,0),1) -> 61.9 | R13: INC | T13: =IFS( AND(G13="AAP", OR(F13="Stronghold", F13="Lean")), "Defend", OR( AND(G13="AAP", OR(F13="Battleground", F13="Highly Volatile", F13="Opposition Lean")), AND(R13="AAP", OR(F13="Battleground", F13="Highly Volatile", F13="Opposition Lean")) ), "Battleground", OR(K13="AAP", M13="AAP", R13="AAP"), "Expand", TRUE, "Long Shot" ) -> Battleground | U13: =IFS( AND(G13="INC", OR(F13="Stronghold", F13="Lean")), "Defend", OR( AND(G13="INC", OR(F13="Battleground", F13="Highly Volatile", F13="Opposition Lean")), AND(R13="INC", OR(F13="Battleground", F13="Highly Volatile", F13="Opposition Lean")) ), "Battleground", OR(K13="INC", M13="INC", R13="INC"), "Expand", TRUE, "Long Shot" ) -> Battleground | V13: =IFS( AND(G13="SAD", OR(F13="Stronghold", F13="Lean")), "Defend", OR( AND(G13="SAD", OR(F13="Battleground", F13="Highly Volatile", F13="Opposition Lean")), AND(R13="SAD", OR(F13="Battleground", F13="Highly Volatile", F13="Opposition Lean")) ), "Battleground", OR(K13="SAD", M13="SAD", R13="SAD"), "Expand", TRUE, "Long Shot" ) -> Expand | W13: =IFS( AND(G13="BJP", OR(F13="Stronghold", F13="Lean")), "Defend", OR( AND(G13="BJP", OR(F13="Battleground", F13="Highly Volatile", F13="Opposition Lean")), AND(R13="BJP", OR(F13="Battleground", F13="Highly Volatile", F13="Opposition Lean")) ), "Battleground", OR(K13="BJP", M13="BJP", R13="BJP"), "Expand", TRUE, "Long Shot" ) -> Long Shot | X13: =IFS(K13="EMERGING", "YES", COUNTIFS(T13:W13, "<>Long Shot", T13:W13, "<>") >= 3, "YES", TRUE, "") -> YES
A14: 11 | B14: Ajnala | C14: Amritsar | D14: Majha | E14: Kuldeep Singh Dhaliwal | F14: =IFS( OR(P14>=75, ((H14<>J14)+(J14<>I14)+(I14<>K14))>=3), "Highly Volatile", AND(COUNTIF(H14:K14, G14)+1>=4, O14<55, P14<65), "Stronghold", AND(COUNTIF(H14:K14, G14)+1>=3, O14<70, P14<75), "Lean", AND(R14<>G14, ((H14=R14)+(J14=R14)+(K14=R14))>=2, O14<60, P14<70), "Opposition Lean", TRUE, "Battleground" ) -> Lean | G14: AAP | H14: INC | I14: AAP | J14: INC | K14: AAP | M14: SAD | N14: 6.47 | O14: {=_xlfn.XLOOKUP(B14, 'Assembly Competitiveness'!$B$4:$B$120,'Assembly Competitiveness'!$O$4:$O$120, "-")} -> 38.5665 | P14: {=_xlfn.XLOOKUP(B14,'Assembly Volatality'!$B$4:$B$120,'Assembly Volatality'!$L$4:$L$120, "-")} -> 44.06 | Q14: =ROUND(0.45*O14+0.4*P14+0.15*IF(H14<>K14,100,0),1) -> 50 | R14: SAD | T14: =IFS( AND(G14="AAP", OR(F14="Stronghold", F14="Lean")), "Defend", OR( AND(G14="AAP", OR(F14="Battleground", F14="Highly Volatile", F14="Opposition Lean")), AND(R14="AAP", OR(F14="Battleground", F14="Highly Volatile", F14="Opposition Lean")) ), "Battleground", OR(K14="AAP", M14="AAP", R14="AAP"), "Expand", TRUE, "Long Shot" ) -> Defend | U14: =IFS( AND(G14="INC", OR(F14="Stronghold", F14="Lean")), "Defend", OR( AND(G14="INC", OR(F14="Battleground", F14="Highly Volatile", F14="Opposition Lean")), AND(R14="INC", OR(F14="Battleground", F14="Highly Volatile", F14="Opposition Lean")) ), "Battleground", OR(K14="INC", M14="INC", R14="INC"), "Expand", TRUE, "Long Shot" ) -> Long Shot | V14: =IFS( AND(G14="SAD", OR(F14="Stronghold", F14="Lean")), "Defend", OR( AND(G14="SAD", OR(F14="Battleground", F14="Highly Volatile", F14="Opposition Lean")), AND(R14="SAD", OR(F14="Battleground", F14="Highly Volatile", F14="Opposition Lean")) ), "Battleground", OR(K14="SAD", M14="SAD", R14="SAD"), "Expand", TRUE, "Long Shot" ) -> Expand | W14: =IFS( AND(G14="BJP", OR(F14="Stronghold", F14="Lean")), "Defend", OR( AND(G14="BJP", OR(F14="Battleground", F14="Highly Volatile", F14="Opposition Lean")), AND(R14="BJP", OR(F14="Battleground", F14="Highly Volatile", F14="Opposition Lean")) ), "Battleground", OR(K14="BJP", M14="BJP", R14="BJP"), "Expand", TRUE, "Long Shot" ) -> Long Shot | X14: =IFS(K14="EMERGING", "YES", COUNTIFS(T14:W14, "<>Long Shot", T14:W14, "<>") >= 3, "YES", TRUE, "")
A15: 12 | B15: Raja Sansi | C15: Amritsar | D15: Majha | E15: Sukhbinder Singh Sarkaria | F15: =IFS( OR(P15>=75, ((H15<>J15)+(J15<>I15)+(I15<>K15))>=3), "Highly Volatile", AND(COUNTIF(H15:K15, G15)+1>=4, O15<55, P15<65), "Stronghold", AND(COUNTIF(H15:K15, G15)+1>=3, O15<70, P15<75), "Lean", AND(R15<>G15, ((H15=R15)+(J15=R15)+(K15=R15))>=2, O15<60, P15<70), "Opposition Lean", TRUE, "Battleground" ) -> Stronghold | G15: INC | H15: INC | I15: INC | J15: INC | K15: INC | M15: SAD | N15: 4.14 | O15: {=_xlfn.XLOOKUP(B15, 'Assembly Competitiveness'!$B$4:$B$120,'Assembly Competitiveness'!$O$4:$O$120, "-")} -> 51.407 | P15: {=_xlfn.XLOOKUP(B15,'Assembly Volatality'!$B$4:$B$120,'Assembly Volatality'!$L$4:$L$120, "-")} -> 3.92 | Q15: =ROUND(0.45*O15+0.4*P15+0.15*IF(H15<>K15,100,0),1) -> 24.7 | R15: SAD | T15: =IFS( AND(G15="AAP", OR(F15="Stronghold", F15="Lean")), "Defend", OR( AND(G15="AAP", OR(F15="Battleground", F15="Highly Volatile", F15="Opposition Lean")), AND(R15="AAP", OR(F15="Battleground", F15="Highly Volatile", F15="Opposition Lean")) ), "Battleground", OR(K15="AAP", M15="AAP", R15="AAP"), "Expand", TRUE, "Long Shot" ) -> Long Shot | U15: =IFS( AND(G15="INC", OR(F15="Stronghold", F15="Lean")), "Defend", OR( AND(G15="INC", OR(F15="Battleground", F15="Highly Volatile", F15="Opposition Lean")), AND(R15="INC", OR(F15="Battleground", F15="Highly Volatile", F15="Opposition Lean")) ), "Battleground", OR(K15="INC", M15="INC", R15="INC"), "Expand", TRUE, "Long Shot" ) -> Defend | V15: =IFS( AND(G15="SAD", OR(F15="Stronghold", F15="Lean")), "Defend", OR( AND(G15="SAD", OR(F15="Battleground", F15="Highly Volatile", F15="Opposition Lean")), AND(R15="SAD", OR(F15="Battleground", F15="Highly Volatile", F15="Opposition Lean")) ), "Battleground", OR(K15="SAD", M15="SAD", R15="SAD"), "Expand", TRUE, "Long Shot" ) -> Expand | W15: =IFS( AND(G15="BJP", OR(F15="Stronghold", F15="Lean")), "Defend", OR( AND(G15="BJP", OR(F15="Battleground", F15="Highly Volatile", F15="Opposition Lean")), AND(R15="BJP", OR(F15="Battleground", F15="Highly Volatile", F15="Opposition Lean")) ), "Battleground", OR(K15="BJP", M15="BJP", R15="BJP"), "Expand", TRUE, "Long Shot" ) -> Long Shot | X15: =IFS(K15="EMERGING", "YES", COUNTIFS(T15:W15, "<>Long Shot", T15:W15, "<>") >= 3, "YES", TRUE, "")
A16: 13 | B16: Majitha | C16: Amritsar | D16: Majha | E16: Ganieve Kaur Majithia | F16: =IFS( OR(P16>=75, ((H16<>J16)+(J16<>I16)+(I16<>K16))>=3), "Highly Volatile", AND(COUNTIF(H16:K16, G16)+1>=4, O16<55, P16<65), "Stronghold", AND(COUNTIF(H16:K16, G16)+1>=3, O16<70, P16<75), "Lean", AND(R16<>G16, ((H16=R16)+(J16=R16)+(K16=R16))>=2, O16<60, P16<70), "Opposition Lean", TRUE, "Battleground" ) -> Stronghold | G16: SAD | H16: SAD | I16: SAD | J16: BJP | K16: SAD | M16: AAP | N16: 21.48 | O16: {=_xlfn.XLOOKUP(B16, 'Assembly Competitiveness'!$B$4:$B$120,'Assembly Competitiveness'!$O$4:$O$120, "-")} -> 2.258 | P16: {=_xlfn.XLOOKUP(B16,'Assembly Volatality'!$B$4:$B$120,'Assembly Volatality'!$L$4:$L$120, "-")} -> 6.42 | Q16: =ROUND(0.45*O16+0.4*P16+0.15*IF(H16<>K16,100,0),1) -> 3.6 | R16: AAP | T16: =IFS( AND(G16="AAP", OR(F16="Stronghold", F16="Lean")), "Defend", OR( AND(G16="AAP", OR(F16="Battleground", F16="Highly Volatile", F16="Opposition Lean")), AND(R16="AAP", OR(F16="Battleground", F16="Highly Volatile", F16="Opposition Lean")) ), "Battleground", OR(K16="AAP", M16="AAP", R16="AAP"), "Expand", TRUE, "Long Shot" ) -> Expand | U16: =IFS( AND(G16="INC", OR(F16="Stronghold", F16="Lean")), "Defend", OR( AND(G16="INC", OR(F16="Battleground", F16="Highly Volatile", F16="Opposition Lean")), AND(R16="INC", OR(F16="Battleground", F16="Highly Volatile", F16="Opposition Lean")) ), "Battleground", OR(K16="INC", M16="INC", R16="INC"), "Expand", TRUE, "Long Shot" ) -> Long Shot | V16: =IFS( AND(G16="SAD", OR(F16="Stronghold", F16="Lean")), "Defend", OR( AND(G16="SAD", OR(F16="Battleground", F16="Highly Volatile", F16="Opposition Lean")), AND(R16="SAD", OR(F16="Battleground", F16="Highly Volatile", F16="Opposition Lean")) ), "Battleground", OR(K16="SAD", M16="SAD", R16="SAD"), "Expand", TRUE, "Long Shot" ) -> Defend | W16: =IFS( AND(G16="BJP", OR(F16="Stronghold", F16="Lean")), "Defend", OR( AND(G16="BJP", OR(F16="Battleground", F16="Highly Volatile", F16="Opposition Lean")), AND(R16="BJP", OR(F16="Battleground", F16="Highly Volatile", F16="Opposition Lean")) ), "Battleground", OR(K16="BJP", M16="BJP", R16="BJP"), "Expand", TRUE, "Long Shot" ) -> Long Shot | X16: =IFS(K16="EMERGING", "YES", COUNTIFS(T16:W16, "<>Long Shot", T16:W16, "<>") >= 3, "YES", TRUE, "")
A17: 14 | B17: Jandiala | C17: Amritsar | D17: Majha | E17: Harbhajan Singh E.T.O. | F17: =IFS( OR(P17>=75, ((H17<>J17)+(J17<>I17)+(I17<>K17))>=3), "Highly Volatile", AND(COUNTIF(H17:K17, G17)+1>=4, O17<55, P17<65), "Stronghold", AND(COUNTIF(H17:K17, G17)+1>=3, O17<70, P17<75), "Lean", AND(R17<>G17, ((H17=R17)+(J17=R17)+(K17=R17))>=2, O17<60, P17<70), "Opposition Lean", TRUE, "Battleground" ) -> Opposition Lean | G17: AAP | H17: INC | I17: AAP | J17: INC | K17: EMERGING | M17: INC | N17: 19.87 | O17: {=_xlfn.XLOOKUP(B17, 'Assembly Competitiveness'!$B$4:$B$120,'Assembly Competitiveness'!$O$4:$O$120, "-")} -> 17.5765 | P17: {=_xlfn.XLOOKUP(B17,'Assembly Volatality'!$B$4:$B$120,'Assembly Volatality'!$L$4:$L$120, "-")} -> 48.08 | Q17: =ROUND(0.45*O17+0.4*P17+0.15*IF(H17<>K17,100,0),1) -> 42.1 | R17: INC | S17: YES | T17: =IFS( AND(G17="AAP", OR(F17="Stronghold", F17="Lean")), "Defend", OR( AND(G17="AAP", OR(F17="Battleground", F17="Highly Volatile", F17="Opposition Lean")), AND(R17="AAP", OR(F17="Battleground", F17="Highly Volatile", F17="Opposition Lean")) ), "Battleground", OR(K17="AAP", M17="AAP", R17="AAP"), "Expand", TRUE, "Long Shot" ) -> Battleground | U17: =IFS( AND(G17="INC", OR(F17="Stronghold", F17="Lean")), "Defend", OR( AND(G17="INC", OR(F17="Battleground", F17="Highly Volatile", F17="Opposition Lean")), AND(R17="INC", OR(F17="Battleground", F17="Highly Volatile", F17="Opposition Lean")) ), "Battleground", OR(K17="INC", M17="INC", R17="INC"), "Expand", TRUE, "Long Shot" ) -> Battleground | V17: =IFS( AND(G17="SAD", OR(F17="Stronghold", F17="Lean")), "Defend", OR( AND(G17="SAD", OR(F17="Battleground", F17="Highly Volatile", F17="Opposition Lean")), AND(R17="SAD", OR(F17="Battleground", F17="Highly Volatile", F17="Opposition Lean")) ), "Battleground", OR(K17="SAD", M17="SAD", R17="SAD"), "Expand", TRUE, "Long Shot" ) -> Long Shot | W17: =IFS( AND(G17="BJP", OR(F17="Stronghold", F17="Lean")), "Defend", OR( AND(G17="BJP", OR(F17="Battleground", F17="Highly Volatile", F17="Opposition Lean")), AND(R17="BJP", OR(F17="Battleground", F17="Highly Volatile", F17="Opposition Lean")) ), "Battleground", OR(K17="BJP", M17="BJP", R17="BJP"), "Expand", TRUE, "Long Shot" ) -> Long Shot | X17: =IFS(K17="EMERGING", "YES", COUNTIFS(T17:W17, "<>Long Shot", T17:W17, "<>") >= 3, "YES", TRUE, "") -> YES
A18: 15 | B18: Amritsar North | C18: Amritsar | D18: Majha | E18: Kunwar Vijay Pratap Singh | F18: =IFS( OR(P18>=75, ((H18<>J18)+(J18<>I18)+(I18<>K18))>=3), "Highly Volatile", AND(COUNTIF(H18:K18, G18)+1>=4, O18<55, P18<65), "Stronghold", AND(COUNTIF(H18:K18, G18)+1>=3, O18<70, P18<75), "Lean", AND(R18<>G18, ((H18=R18)+(J18=R18)+(K18=R18))>=2, O18<60, P18<70), "Opposition Lean", TRUE, "Battleground" ) -> Battleground | G18: AAP | H18: INC | I18: AAP | J18: INC | K18: BJP | M18: SAD | N18: 23.03 | O18: {=_xlfn.XLOOKUP(B18, 'Assembly Competitiveness'!$B$4:$B$120,'Assembly Competitiveness'!$O$4:$O$120, "-")} -> 22.188 | P18: {=_xlfn.XLOOKUP(B18,'Assembly Volatality'!$B$4:$B$120,'Assembly Volatality'!$L$4:$L$120, "-")} -> 56.29 | Q18: =ROUND(0.45*O18+0.4*P18+0.15*IF(H18<>K18,100,0),1) -> 47.5 | R18: SAD | S18: YES | T18: =IFS( AND(G18="AAP", OR(F18="Stronghold", F18="Lean")), "Defend", OR( AND(G18="AAP", OR(F18="Battleground", F18="Highly Volatile", F18="Opposition Lean")), AND(R18="AAP", OR(F18="Battleground", F18="Highly Volatile", F18="Opposition Lean")) ), "Battleground", OR(K18="AAP", M18="AAP", R18="AAP"), "Expand", TRUE, "Long Shot" ) -> Battleground | U18: =IFS( AND(G18="INC", OR(F18="Stronghold", F18="Lean")), "Defend", OR( AND(G18="INC", OR(F18="Battleground", F18="Highly Volatile", F18="Opposition Lean")), AND(R18="INC", OR(F18="Battleground", F18="Highly Volatile", F18="Opposition Lean")) ), "Battleground", OR(K18="INC", M18="INC", R18="INC"), "Expand", TRUE, "Long Shot" ) -> Long Shot | V18: =IFS( AND(G18="SAD", OR(F18="Stronghold", F18="Lean")), "Defend", OR( AND(G18="SAD", OR(F18="Battleground", F18="Highly Volatile", F18="Opposition Lean")), AND(R18="SAD", OR(F18="Battleground", F18="Highly Volatile", F18="Opposition Lean")) ), "Battleground", OR(K18="SAD", M18="SAD", R18="SAD"), "Expand", TRUE, "Long Shot" ) -> Battleground | W18: =IFS( AND(G18="BJP", OR(F18="Stronghold", F18="Lean")), "Defend", OR( AND(G18="BJP", OR(F18="Battleground", F18="Highly Volatile", F18="Opposition Lean")), AND(R18="BJP", OR(F18="Battleground", F18="Highly Volatile", F18="Opposition Lean")) ), "Battleground", OR(K18="BJP", M18="BJP", R18="BJP"), "Expand", TRUE, "Long Shot" ) -> Expand | X18: =IFS(K18="EMERGING", "YES", COUNTIFS(T18:W18, "<>Long Shot", T18:W18, "<>") >= 3, "YES", TRUE, "") -> YES
A19: 16 | B19: Amritsar West | C19: Amritsar | D19: Majha | E19: Dr. Jasbir Singh Sandhu | F19: =IFS( OR(P19>=75, ((H19<>J19)+(J19<>I19)+(I19<>K19))>=3), "Highly Volatile", AND(COUNTIF(H19:K19, G19)+1>=4, O19<55, P19<65), "Stronghold", AND(COUNTIF(H19:K19, G19)+1>=3, O19<70, P19<75), "Lean", AND(R19<>G19, ((H19=R19)+(J19=R19)+(K19=R19))>=2, O19<60, P19<70), "Opposition Lean", TRUE, "Battleground" ) -> Opposition Lean | G19: AAP | H19: INC | I19: AAP | J19: INC | K19: INC | M19: INC | N19: 37.33 | O19: {=_xlfn.XLOOKUP(B19, 'Assembly Competitiveness'!$B$4:$B$120,'Assembly Competitiveness'!$O$4:$O$120, "-")} -> 14.872 | P19: {=_xlfn.XLOOKUP(B19,'Assembly Volatality'!$B$4:$B$120,'Assembly Volatality'!$L$4:$L$120, "-")} -> 56.28 | Q19: =ROUND(0.45*O19+0.4*P19+0.15*IF(H19<>K19,100,0),1) -> 29.2 | R19: INC | S19: YES | T19: =IFS( AND(G19="AAP", OR(F19="Stronghold", F19="Lean")), "Defend", OR( AND(G19="AAP", OR(F19="Battleground", F19="Highly Volatile", F19="Opposition Lean")), AND(R19="AAP", OR(F19="Battleground", F19="Highly Volatile", F19="Opposition Lean")) ), "Battleground", OR(K19="AAP", M19="AAP", R19="AAP"), "Expand", TRUE, "Long Shot" ) -> Battleground | U19: =IFS( AND(G19="INC", OR(F19="Stronghold", F19="Lean")), "Defend", OR( AND(G19="INC", OR(F19="Battleground", F19="Highly Volatile", F19="Opposition Lean")), AND(R19="INC", OR(F19="Battleground", F19="Highly Volatile", F19="Opposition Lean")) ), "Battleground", OR(K19="INC", M19="INC", R19="INC"), "Expand", TRUE, "Long Shot" ) -> Battleground | V19: =IFS( AND(G19="SAD", OR(F19="Stronghold", F19="Lean")), "Defend", OR( AND(G19="SAD", OR(F19="Battleground", F19="Highly Volatile", F19="Opposition Lean")), AND(R19="SAD", OR(F19="Battleground", F19="Highly Volatile", F19="Opposition Lean")) ), "Battleground", OR(K19="SAD", M19="SAD", R19="SAD"), "Expand", TRUE, "Long Shot" ) -> Long Shot | W19: =IFS( AND(G19="BJP", OR(F19="Stronghold", F19="Lean")), "Defend", OR( AND(G19="BJP", OR(F19="Battleground", F19="Highly Volatile", F19="Opposition Lean")), AND(R19="BJP", OR(F19="Battleground", F19="Highly Volatile", F19="Opposition Lean")) ), "Battleground", OR(K19="BJP", M19="BJP", R19="BJP"), "Expand", TRUE, "Long Shot" ) -> Long Shot | X19: =IFS(K19="EMERGING", "YES", COUNTIFS(T19:W19, "<>Long Shot", T19:W19, "<>") >= 3, "YES", TRUE, "")
A20: 17 | B20: Amritsar Central | C20: Amritsar | D20: Majha | E20: Ajay Gupta | F20: =IFS( OR(P20>=75, ((H20<>J20)+(J20<>I20)+(I20<>K20))>=3), "Highly Volatile", AND(COUNTIF(H20:K20, G20)+1>=4, O20<55, P20<65), "Stronghold", AND(COUNTIF(H20:K20, G20)+1>=3, O20<70, P20<75), "Lean", AND(R20<>G20, ((H20=R20)+(J20=R20)+(K20=R20))>=2, O20<60, P20<70), "Opposition Lean", TRUE, "Battleground" ) -> Opposition Lean | G20: AAP | H20: INC | I20: AAP | J20: INC | K20: BJP | M20: INC | N20: 16.21 | O20: {=_xlfn.XLOOKUP(B20, 'Assembly Competitiveness'!$B$4:$B$120,'Assembly Competitiveness'!$O$4:$O$120, "-")} -> 21.4515 | P20: {=_xlfn.XLOOKUP(B20,'Assembly Volatality'!$B$4:$B$120,'Assembly Volatality'!$L$4:$L$120, "-")} -> 54.11 | Q20: =ROUND(0.45*O20+0.4*P20+0.15*IF(H20<>K20,100,0),1) -> 46.3 | R20: INC | S20: YES | T20: =IFS( AND(G20="AAP", OR(F20="Stronghold", F20="Lean")), "Defend", OR( AND(G20="AAP", OR(F20="Battleground", F20="Highly Volatile", F20="Opposition Lean")), AND(R20="AAP", OR(F20="Battleground", F20="Highly Volatile", F20="Opposition Lean")) ), "Battleground", OR(K20="AAP", M20="AAP", R20="AAP"), "Expand", TRUE, "Long Shot" ) -> Battleground | U20: =IFS( AND(G20="INC", OR(F20="Stronghold", F20="Lean")), "Defend", OR( AND(G20="INC", OR(F20="Battleground", F20="Highly Volatile", F20="Opposition Lean")), AND(R20="INC", OR(F20="Battleground", F20="Highly Volatile", F20="Opposition Lean")) ), "Battleground", OR(K20="INC", M20="INC", R20="INC"), "Expand", TRUE, "Long Shot" ) -> Battleground | V20: =IFS( AND(G20="SAD", OR(F20="Stronghold", F20="Lean")), "Defend", OR( AND(G20="SAD", OR(F20="Battleground", F20="Highly Volatile", F20="Opposition Lean")), AND(R20="SAD", OR(F20="Battleground", F20="Highly Volatile", F20="Opposition Lean")) ), "Battleground", OR(K20="SAD", M20="SAD", R20="SAD"), "Expand", TRUE, "Long Shot" ) -> Long Shot | W20: =IFS( AND(G20="BJP", OR(F20="Stronghold", F20="Lean")), "Defend", OR( AND(G20="BJP", OR(F20="Battleground", F20="Highly Volatile", F20="Opposition Lean")), AND(R20="BJP", OR(F20="Battleground", F20="Highly Volatile", F20="Opposition Lean")) ), "Battleground", OR(K20="BJP", M20="BJP", R20="BJP"), "Expand", TRUE, "Long Shot" ) -> Expand | X20: =IFS(K20="EMERGING", "YES", COUNTIFS(T20:W20, "<>Long Shot", T20:W20, "<>") >= 3, "YES", TRUE, "") -> YES
